Workbook

Sheet Suggested Guidance
B2: Overview
B4: The Capital Call & Distribution Template was developed to standardize the accounting details captured within a capital call and distribution notice. It has been redeveloped to align with the updated ILPA Reporting Template and new ILPA Performance Template and features a more user-friendly design that can be used to capture details to support reporting with the Performance Template.
B6: The guidance below is intended to communicate the expectations and context necessary to provide industry participants with a better understanding of the Capital Call & Distribution Template.
B9: Guidance and Supplemental Resources
B11: Refer to the links below to access the complete Suggested Guidance document, as well as all supplemental resources available on the ILPA website:
B13: Suggested Guidance PDF
B14: Supplemental Resources
B16: The full Capital Call & Distributions Template Suggested Guidance and Supplemental Resources linked above provide the detailed context and clarifications to allow LPs, GPs and Service Providers to utilize the Template most effectively. ILPA encourages interested parties to see the ILPA website (below) for the latest documentation. Additionally, please reach out to the Templates Support inbox below with any questions or suggestions for additional clarity.
B18: www.ilpa.org
B19: templatesupport@ilpa.org
B22: ILPA Capital Call & Distribution Template (v. 2.0) – This packet was last updated on September 10, 2025
B24: © 2025 Institutional Limited Partners Association. All rights reserved.

Sheet Call & Distribution Template
B1: ILPA Capital Call & Distribution Template | F1: Notice Date | G1: 45658
F2: Due Date | G2: 45671
B3: Fund Name | C3: Best Practices Fund II, L.P.
B4: Fund Currency | C4: USD
B5: Fund Size | C5: 2000000000 | F5: Contributions | G5: Distributions | H5: Net Cash Flow
B6: GP Commitment Amount | C6: 40000000 | E6: Fund Amount (Current Notice) | F6: 2500000 | G6: 0 | H6: =SUM(F6:G6) -> 2500000
F8: Inside Fund
F9: Contributions | G9: Distributions | H9: Net Cash Flow
B10: LP / ID Number | C10: LP #5 | E10: LP Amount (Current Notice) | F10: {=SUM(SUMIFS($K$24:$K$53,$L$24:$L$53,"Inside",$E$24:$E$53,{"Capital Call: Deemed GP Contribution from LPs","Capital Call: Total Amount - Inside Fund","Capital Call: Total Amount - Outside Fund","Capital Call: Investments","Capital Call: Management Fees","Capital Call: Partnership Expenses","Capital Call: Placement Agent Fees","Capital Call: Subsequent Close Interest","Capital Call: Working Capital","Capital Call: Fund-level Subscription Facility Fees/Interest","Capital Call: Other (Provide explanation in far-left column)","Negative Contribution: Return of Excess Capital Called","Negative Contribution: Return of Excess Capital Called - Investments","Negative Contribution: Return of Excess Capital Called - Management Fees/Partnership Expenses"}))} -> 20000 | G10: {=SUM(SUMIFS($K$24:$K$53,$L$24:$L$53,"Inside",$E$24:$E$53,{"Distribution: Carry","Distribution: Clawback","Distribution: Income","Distribution: Dividends","Distribution: Other (Provide explanation in far-left column)","Distribution: Realized Gain / (Loss) - Cash (input negative value for loss)","Distribution: Realized Gain / (Loss) - Stock (input negative value for loss)","Distribution: Return of Capital - Cash","Distribution: Return of Capital - Stock","Distribution: From NAV-Based Facility","Distribution: Subsequent Close Interest","Distribution: Tax Withheld","Distribution: Refund of Tax Withheld"}))} -> 0 | H10: =SUM(F10:G10) -> 20000
B11: LP Commitment | C11: 20000000 | E11: As a % of Fund Amount | F11: =IFERROR(ABS(F10/F6),"---") -> 0.008 | G11: =IFERROR(ABS(G10/G6),"---") -> --- | H11: =IFERROR(ABS(H10/H6),"---") -> 0.008
B12: LP % of Fund (LP Commitment / Fund Size) | C12: =C11/C5 -> 0.01 | E12: Cumulative LP Amount (Prior to Current Notice) | F12: 0 | G12: 0
B13: LP % of Unfunded (% of Total Fund Unfunded) - Optional | E13: Cumulative LP Amount (Including Current Notice) | F13: =F10+F12 -> 20000 | G13: =G10+G12 -> 0
F15: Outside Fund
B16: LP Unfunded Balance (Prior to Current Notice) | C16: 14500000 | F16: Outflow from LP | G16: Inflow to LP | H16: Net Cash Flow
B17: Impact on LP Unfunded Balance (Current Notice) | C17: =SUM(J24:J49) -> 0 | E17: LP Amount (Current Notice) | F17: {=SUM(SUMIFS($K$24:$K$53,$L$24:$L$53,"Outside",$E$24:$E$53,{"Capital Call: Deemed GP Contribution from LPs","Capital Call: Total Amount - Inside Fund","Capital Call: Total Amount - Outside Fund","Capital Call: Investments","Capital Call: Management Fees","Capital Call: Partnership Expenses","Capital Call: Placement Agent Fees","Capital Call: Subsequent Close Interest","Capital Call: Working Capital","Capital Call: Fund-level Subscription Facility Fees/Interest","Capital Call: Other (Provide explanation in far-left column)","Distribution: Carry","Distribution: Tax Withheld"}))} -> 0 | G17: {=SUM(SUMIFS($K$24:$K$53,$L$24:$L$53,"Outside",$E$24:$E$53,{"Distribution: Clawback","Distribution: Income","Distribution: Dividends","Distribution: Other (Provide explanation in far-left column)","Distribution: Realized Gain / (Loss) - Cash (input negative value for loss)","Distribution: Realized Gain / (Loss) - Stock (input negative value for loss)","Distribution: Return of Capital - Cash","Distribution: Return of Capital - Stock","Distribution: From NAV-Based Facility","Distribution: Subsequent Close Interest","Negative Contribution: Return of Excess Capital Called","Negative Contribution: Return of Excess Capital Called - Investments","Negative Contribution: Return of Excess Capital Called - Management Fees/Partnership Expenses","Distribution: Refund of Tax Withheld"}))} -> 0 | H17: =SUM(F17:G17) -> 0
B18: Expired/Released Commitments (Input negative value)
B19: Other Unfunded Adjustment
B20: LP Unfunded Balance (Including Current Notice) | C20: =SUM(C16:D19) -> 14500000 | E20: LP Total Net Amount Called / (Distributed) | F20: =SUMIF(K24:K49,">-999999999999999") -> 20000
B23: Transaction Description | E23: Transaction Type | H23: LP Amount (Input Positive Values) | I23: Impact on Unfunded Commitment (Increase/Decrease) | J23: Impact on Unfunded Commitment (Value) | K23: Net Amount Called / (Distributed) (Value) | L23: Inside / Outside Fund
B24: Call for follow-on investment into XYZ company | E24: Capital Call: Investments | H24: 20000 | I24: No Impact | J24: {=IFERROR(_xlfn.IFS(AND(I24="Decrease",H24<0),H24,AND(I24="Decrease",H24>0),-H24,AND(I24="Increase",H24>0),H24,AND(I24="Increase",H24<0),-H24,AND(I24="No Impact",H24=0),"0.00"),"0.00")} -> 0.00 | K24: {=IFERROR(_xlfn.IFS( ISNUMBER(SEARCH("Capital call:",E24)),H24, ISNUMBER(SEARCH("Distribution: Carry",E24)),H24, ISNUMBER(SEARCH("Distribution: Clawback",E24)),-H24, ISNUMBER(SEARCH("Distribution: Income",E24)),-H24, ISNUMBER(SEARCH("Distribution: Dividends",E24)),-H24, ISNUMBER(SEARCH("Distribution: Other (Provide explanation in far-left column)",E24)),-H24, ISNUMBER(SEARCH("Distribution: Realized Gain / (Loss) - Cash (input negative value for loss)",E24)),-H24, ISNUMBER(SEARCH("Distribution: Realized Gain / (Loss) - Stock (input negative value for loss)",E24)),-H24, ISNUMBER(SEARCH("Distribution: Return of Capital - Cash",E24)),-H24, ISNUMBER(SEARCH("Distribution: Return of Capital - Stock",E24)),-H24, ISNUMBER(SEARCH("Distribution: From NAV-Based Facility",E24)),-H24, ISNUMBER(SEARCH("Negative Contribution: Return of Excess Capital Called",E24)),-H24, ISNUMBER(SEARCH("Negative Contribution: Return of Excess Capital Called - Investments",E24)),-H24, ISNUMBER(SEARCH("Negative Contribution: Return of Excess Capital Called - Management Fees/Partnership Expenses",E24)),-H24, ISNUMBER(SEARCH("Distribution: Subsequent Close Interest",E24)),-H24, ISNUMBER(SEARCH("Distribution: Tax Withheld",E24)),H24, ISNUMBER(SEARCH("Distribution: Refund of Tax Withheld",E24)),-H24),0)} -> 20000 | L24: Inside
J25: {=IFERROR(_xlfn.IFS(AND(I25="Decrease",H25<0),H25,AND(I25="Decrease",H25>0),-H25,AND(I25="Increase",H25>0),H25,AND(I25="Increase",H25<0),-H25,AND(I25="No Impact",H25=0),"0.00"),"0.00")} -> 0.00 | K25: {=IFERROR(_xlfn.IFS( ISNUMBER(SEARCH("Capital call:",E25)),H25, ISNUMBER(SEARCH("Distribution: Carry",E25)),H25, ISNUMBER(SEARCH("Distribution: Clawback",E25)),-H25, ISNUMBER(SEARCH("Distribution: Income",E25)),-H25, ISNUMBER(SEARCH("Distribution: Dividends",E25)),-H25, ISNUMBER(SEARCH("Distribution: Other (Provide explanation in far-left column)",E25)),-H25, ISNUMBER(SEARCH("Distribution: Realized Gain / (Loss) - Cash (input negative value for loss)",E25)),-H25, ISNUMBER(SEARCH("Distribution: Realized Gain / (Loss) - Stock (input negative value for loss)",E25)),-H25, ISNUMBER(SEARCH("Distribution: Return of Capital - Cash",E25)),-H25, ISNUMBER(SEARCH("Distribution: Return of Capital - Stock",E25)),-H25, ISNUMBER(SEARCH("Distribution: From NAV-Based Facility",E25)),-H25, ISNUMBER(SEARCH("Negative Contribution: Return of Excess Capital Called",E25)),-H25, ISNUMBER(SEARCH("Negative Contribution: Return of Excess Capital Called - Investments",E25)),-H25, ISNUMBER(SEARCH("Negative Contribution: Return of Excess Capital Called - Management Fees/Partnership Expenses",E25)),-H25, ISNUMBER(SEARCH("Distribution: Subsequent Close Interest",E25)),-H25, ISNUMBER(SEARCH("Distribution: Tax Withheld",E25)),H25, ISNUMBER(SEARCH("Distribution: Refund of Tax Withheld",E25)),-H25),0)} -> 0
J26: {=IFERROR(_xlfn.IFS(AND(I26="Decrease",H26<0),H26,AND(I26="Decrease",H26>0),-H26,AND(I26="Increase",H26>0),H26,AND(I26="Increase",H26<0),-H26,AND(I26="No Impact",H26=0),"0.00"),"0.00")} -> 0.00 | K26: {=IFERROR(_xlfn.IFS( ISNUMBER(SEARCH("Capital call:",E26)),H26, ISNUMBER(SEARCH("Distribution: Carry",E26)),H26, ISNUMBER(SEARCH("Distribution: Clawback",E26)),-H26, ISNUMBER(SEARCH("Distribution: Income",E26)),-H26, ISNUMBER(SEARCH("Distribution: Dividends",E26)),-H26, ISNUMBER(SEARCH("Distribution: Other (Provide explanation in far-left column)",E26)),-H26, ISNUMBER(SEARCH("Distribution: Realized Gain / (Loss) - Cash (input negative value for loss)",E26)),-H26, ISNUMBER(SEARCH("Distribution: Realized Gain / (Loss) - Stock (input negative value for loss)",E26)),-H26, ISNUMBER(SEARCH("Distribution: Return of Capital - Cash",E26)),-H26, ISNUMBER(SEARCH("Distribution: Return of Capital - Stock",E26)),-H26, ISNUMBER(SEARCH("Distribution: From NAV-Based Facility",E26)),-H26, ISNUMBER(SEARCH("Negative Contribution: Return of Excess Capital Called",E26)),-H26, ISNUMBER(SEARCH("Negative Contribution: Return of Excess Capital Called - Investments",E26)),-H26, ISNUMBER(SEARCH("Negative Contribution: Return of Excess Capital Called - Management Fees/Partnership Expenses",E26)),-H26, ISNUMBER(SEARCH("Distribution: Subsequent Close Interest",E26)),-H26, ISNUMBER(SEARCH("Distribution: Tax Withheld",E26)),H26, ISNUMBER(SEARCH("Distribution: Refund of Tax Withheld",E26)),-H26),0)} -> 0
J27: {=IFERROR(_xlfn.IFS(AND(I27="Decrease",H27<0),H27,AND(I27="Decrease",H27>0),-H27,AND(I27="Increase",H27>0),H27,AND(I27="Increase",H27<0),-H27,AND(I27="No Impact",H27=0),"0.00"),"0.00")} -> 0.00 | K27: {=IFERROR(_xlfn.IFS( ISNUMBER(SEARCH("Capital call:",E27)),H27, ISNUMBER(SEARCH("Distribution: Carry",E27)),H27, ISNUMBER(SEARCH("Distribution: Clawback",E27)),-H27, ISNUMBER(SEARCH("Distribution: Income",E27)),-H27, ISNUMBER(SEARCH("Distribution: Dividends",E27)),-H27, ISNUMBER(SEARCH("Distribution: Other (Provide explanation in far-left column)",E27)),-H27, ISNUMBER(SEARCH("Distribution: Realized Gain / (Loss) - Cash (input negative value for loss)",E27)),-H27, ISNUMBER(SEARCH("Distribution: Realized Gain / (Loss) - Stock (input negative value for loss)",E27)),-H27, ISNUMBER(SEARCH("Distribution: Return of Capital - Cash",E27)),-H27, ISNUMBER(SEARCH("Distribution: Return of Capital - Stock",E27)),-H27, ISNUMBER(SEARCH("Distribution: From NAV-Based Facility",E27)),-H27, ISNUMBER(SEARCH("Negative Contribution: Return of Excess Capital Called",E27)),-H27, ISNUMBER(SEARCH("Negative Contribution: Return of Excess Capital Called - Investments",E27)),-H27, ISNUMBER(SEARCH("Negative Contribution: Return of Excess Capital Called - Management Fees/Partnership Expenses",E27)),-H27, ISNUMBER(SEARCH("Distribution: Subsequent Close Interest",E27)),-H27, ISNUMBER(SEARCH("Distribution: Tax Withheld",E27)),H27, ISNUMBER(SEARCH("Distribution: Refund of Tax Withheld",E27)),-H27),0)} -> 0
J28: {=IFERROR(_xlfn.IFS(AND(I28="Decrease",H28<0),H28,AND(I28="Decrease",H28>0),-H28,AND(I28="Increase",H28>0),H28,AND(I28="Increase",H28<0),-H28,AND(I28="No Impact",H28=0),"0.00"),"0.00")} -> 0.00 | K28: {=IFERROR(_xlfn.IFS( ISNUMBER(SEARCH("Capital call:",E28)),H28, ISNUMBER(SEARCH("Distribution: Carry",E28)),H28, ISNUMBER(SEARCH("Distribution: Clawback",E28)),-H28, ISNUMBER(SEARCH("Distribution: Income",E28)),-H28, ISNUMBER(SEARCH("Distribution: Dividends",E28)),-H28, ISNUMBER(SEARCH("Distribution: Other (Provide explanation in far-left column)",E28)),-H28, ISNUMBER(SEARCH("Distribution: Realized Gain / (Loss) - Cash (input negative value for loss)",E28)),-H28, ISNUMBER(SEARCH("Distribution: Realized Gain / (Loss) - Stock (input negative value for loss)",E28)),-H28, ISNUMBER(SEARCH("Distribution: Return of Capital - Cash",E28)),-H28, ISNUMBER(SEARCH("Distribution: Return of Capital - Stock",E28)),-H28, ISNUMBER(SEARCH("Distribution: From NAV-Based Facility",E28)),-H28, ISNUMBER(SEARCH("Negative Contribution: Return of Excess Capital Called",E28)),-H28, ISNUMBER(SEARCH("Negative Contribution: Return of Excess Capital Called - Investments",E28)),-H28, ISNUMBER(SEARCH("Negative Contribution: Return of Excess Capital Called - Management Fees/Partnership Expenses",E28)),-H28, ISNUMBER(SEARCH("Distribution: Subsequent Close Interest",E28)),-H28, ISNUMBER(SEARCH("Distribution: Tax Withheld",E28)),H28, ISNUMBER(SEARCH("Distribution: Refund of Tax Withheld",E28)),-H28),0)} -> 0
J29: {=IFERROR(_xlfn.IFS(AND(I29="Decrease",H29<0),H29,AND(I29="Decrease",H29>0),-H29,AND(I29="Increase",H29>0),H29,AND(I29="Increase",H29<0),-H29,AND(I29="No Impact",H29=0),"0.00"),"0.00")} -> 0.00 | K29: {=IFERROR(_xlfn.IFS( ISNUMBER(SEARCH("Capital call:",E29)),H29, ISNUMBER(SEARCH("Distribution: Carry",E29)),H29, ISNUMBER(SEARCH("Distribution: Clawback",E29)),-H29, ISNUMBER(SEARCH("Distribution: Income",E29)),-H29, ISNUMBER(SEARCH("Distribution: Dividends",E29)),-H29, ISNUMBER(SEARCH("Distribution: Other (Provide explanation in far-left column)",E29)),-H29, ISNUMBER(SEARCH("Distribution: Realized Gain / (Loss) - Cash (input negative value for loss)",E29)),-H29, ISNUMBER(SEARCH("Distribution: Realized Gain / (Loss) - Stock (input negative value for loss)",E29)),-H29, ISNUMBER(SEARCH("Distribution: Return of Capital - Cash",E29)),-H29, ISNUMBER(SEARCH("Distribution: Return of Capital - Stock",E29)),-H29, ISNUMBER(SEARCH("Distribution: From NAV-Based Facility",E29)),-H29, ISNUMBER(SEARCH("Negative Contribution: Return of Excess Capital Called",E29)),-H29, ISNUMBER(SEARCH("Negative Contribution: Return of Excess Capital Called - Investments",E29)),-H29, ISNUMBER(SEARCH("Negative Contribution: Return of Excess Capital Called - Management Fees/Partnership Expenses",E29)),-H29, ISNUMBER(SEARCH("Distribution: Subsequent Close Interest",E29)),-H29, ISNUMBER(SEARCH("Distribution: Tax Withheld",E29)),H29, ISNUMBER(SEARCH("Distribution: Refund of Tax Withheld",E29)),-H29),0)} -> 0
J30: {=IFERROR(_xlfn.IFS(AND(I30="Decrease",H30<0),H30,AND(I30="Decrease",H30>0),-H30,AND(I30="Increase",H30>0),H30,AND(I30="Increase",H30<0),-H30,AND(I30="No Impact",H30=0),"0.00"),"0.00")} -> 0.00 | K30: {=IFERROR(_xlfn.IFS( ISNUMBER(SEARCH("Capital call:",E30)),H30, ISNUMBER(SEARCH("Distribution: Carry",E30)),H30, ISNUMBER(SEARCH("Distribution: Clawback",E30)),-H30, ISNUMBER(SEARCH("Distribution: Income",E30)),-H30, ISNUMBER(SEARCH("Distribution: Dividends",E30)),-H30, ISNUMBER(SEARCH("Distribution: Other (Provide explanation in far-left column)",E30)),-H30, ISNUMBER(SEARCH("Distribution: Realized Gain / (Loss) - Cash (input negative value for loss)",E30)),-H30, ISNUMBER(SEARCH("Distribution: Realized Gain / (Loss) - Stock (input negative value for loss)",E30)),-H30, ISNUMBER(SEARCH("Distribution: Return of Capital - Cash",E30)),-H30, ISNUMBER(SEARCH("Distribution: Return of Capital - Stock",E30)),-H30, ISNUMBER(SEARCH("Distribution: From NAV-Based Facility",E30)),-H30, ISNUMBER(SEARCH("Negative Contribution: Return of Excess Capital Called",E30)),-H30, ISNUMBER(SEARCH("Negative Contribution: Return of Excess Capital Called - Investments",E30)),-H30, ISNUMBER(SEARCH("Negative Contribution: Return of Excess Capital Called - Management Fees/Partnership Expenses",E30)),-H30, ISNUMBER(SEARCH("Distribution: Subsequent Close Interest",E30)),-H30, ISNUMBER(SEARCH("Distribution: Tax Withheld",E30)),H30, ISNUMBER(SEARCH("Distribution: Refund of Tax Withheld",E30)),-H30),0)} -> 0
J31: {=IFERROR(_xlfn.IFS(AND(I31="Decrease",H31<0),H31,AND(I31="Decrease",H31>0),-H31,AND(I31="Increase",H31>0),H31,AND(I31="Increase",H31<0),-H31,AND(I31="No Impact",H31=0),"0.00"),"0.00")} -> 0.00 | K31: {=IFERROR(_xlfn.IFS( ISNUMBER(SEARCH("Capital call:",E31)),H31, ISNUMBER(SEARCH("Distribution: Carry",E31)),H31, ISNUMBER(SEARCH("Distribution: Clawback",E31)),-H31, ISNUMBER(SEARCH("Distribution: Income",E31)),-H31, ISNUMBER(SEARCH("Distribution: Dividends",E31)),-H31, ISNUMBER(SEARCH("Distribution: Other (Provide explanation in far-left column)",E31)),-H31, ISNUMBER(SEARCH("Distribution: Realized Gain / (Loss) - Cash (input negative value for loss)",E31)),-H31, ISNUMBER(SEARCH("Distribution: Realized Gain / (Loss) - Stock (input negative value for loss)",E31)),-H31, ISNUMBER(SEARCH("Distribution: Return of Capital - Cash",E31)),-H31, ISNUMBER(SEARCH("Distribution: Return of Capital - Stock",E31)),-H31, ISNUMBER(SEARCH("Distribution: From NAV-Based Facility",E31)),-H31, ISNUMBER(SEARCH("Negative Contribution: Return of Excess Capital Called",E31)),-H31, ISNUMBER(SEARCH("Negative Contribution: Return of Excess Capital Called - Investments",E31)),-H31, ISNUMBER(SEARCH("Negative Contribution: Return of Excess Capital Called - Management Fees/Partnership Expenses",E31)),-H31, ISNUMBER(SEARCH("Distribution: Subsequent Close Interest",E31)),-H31, ISNUMBER(SEARCH("Distribution: Tax Withheld",E31)),H31, ISNUMBER(SEARCH("Distribution: Refund of Tax Withheld",E31)),-H31),0)} -> 0
J32: {=IFERROR(_xlfn.IFS(AND(I32="Decrease",H32<0),H32,AND(I32="Decrease",H32>0),-H32,AND(I32="Increase",H32>0),H32,AND(I32="Increase",H32<0),-H32,AND(I32="No Impact",H32=0),"0.00"),"0.00")} -> 0.00 | K32: {=IFERROR(_xlfn.IFS( ISNUMBER(SEARCH("Capital call:",E32)),H32, ISNUMBER(SEARCH("Distribution: Carry",E32)),H32, ISNUMBER(SEARCH("Distribution: Clawback",E32)),-H32, ISNUMBER(SEARCH("Distribution: Income",E32)),-H32, ISNUMBER(SEARCH("Distribution: Dividends",E32)),-H32, ISNUMBER(SEARCH("Distribution: Other (Provide explanation in far-left column)",E32)),-H32, ISNUMBER(SEARCH("Distribution: Realized Gain / (Loss) - Cash (input negative value for loss)",E32)),-H32, ISNUMBER(SEARCH("Distribution: Realized Gain / (Loss) - Stock (input negative value for loss)",E32)),-H32, ISNUMBER(SEARCH("Distribution: Return of Capital - Cash",E32)),-H32, ISNUMBER(SEARCH("Distribution: Return of Capital - Stock",E32)),-H32, ISNUMBER(SEARCH("Distribution: From NAV-Based Facility",E32)),-H32, ISNUMBER(SEARCH("Negative Contribution: Return of Excess Capital Called",E32)),-H32, ISNUMBER(SEARCH("Negative Contribution: Return of Excess Capital Called - Investments",E32)),-H32, ISNUMBER(SEARCH("Negative Contribution: Return of Excess Capital Called - Management Fees/Partnership Expenses",E32)),-H32, ISNUMBER(SEARCH("Distribution: Subsequent Close Interest",E32)),-H32, ISNUMBER(SEARCH("Distribution: Tax Withheld",E32)),H32, ISNUMBER(SEARCH("Distribution: Refund of Tax Withheld",E32)),-H32),0)} -> 0
J33: {=IFERROR(_xlfn.IFS(AND(I33="Decrease",H33<0),H33,AND(I33="Decrease",H33>0),-H33,AND(I33="Increase",H33>0),H33,AND(I33="Increase",H33<0),-H33,AND(I33="No Impact",H33=0),"0.00"),"0.00")} -> 0.00 | K33: {=IFERROR(_xlfn.IFS( ISNUMBER(SEARCH("Capital call:",E33)),H33, ISNUMBER(SEARCH("Distribution: Carry",E33)),H33, ISNUMBER(SEARCH("Distribution: Clawback",E33)),-H33, ISNUMBER(SEARCH("Distribution: Income",E33)),-H33, ISNUMBER(SEARCH("Distribution: Dividends",E33)),-H33, ISNUMBER(SEARCH("Distribution: Other (Provide explanation in far-left column)",E33)),-H33, ISNUMBER(SEARCH("Distribution: Realized Gain / (Loss) - Cash (input negative value for loss)",E33)),-H33, ISNUMBER(SEARCH("Distribution: Realized Gain / (Loss) - Stock (input negative value for loss)",E33)),-H33, ISNUMBER(SEARCH("Distribution: Return of Capital - Cash",E33)),-H33, ISNUMBER(SEARCH("Distribution: Return of Capital - Stock",E33)),-H33, ISNUMBER(SEARCH("Distribution: From NAV-Based Facility",E33)),-H33, ISNUMBER(SEARCH("Negative Contribution: Return of Excess Capital Called",E33)),-H33, ISNUMBER(SEARCH("Negative Contribution: Return of Excess Capital Called - Investments",E33)),-H33, ISNUMBER(SEARCH("Negative Contribution: Return of Excess Capital Called - Management Fees/Partnership Expenses",E33)),-H33, ISNUMBER(SEARCH("Distribution: Subsequent Close Interest",E33)),-H33, ISNUMBER(SEARCH("Distribution: Tax Withheld",E33)),H33, ISNUMBER(SEARCH("Distribution: Refund of Tax Withheld",E33)),-H33),0)} -> 0
J34: {=IFERROR(_xlfn.IFS(AND(I34="Decrease",H34<0),H34,AND(I34="Decrease",H34>0),-H34,AND(I34="Increase",H34>0),H34,AND(I34="Increase",H34<0),-H34,AND(I34="No Impact",H34=0),"0.00"),"0.00")} -> 0.00 | K34: {=IFERROR(_xlfn.IFS( ISNUMBER(SEARCH("Capital call:",E34)),H34, ISNUMBER(SEARCH("Distribution: Carry",E34)),H34, ISNUMBER(SEARCH("Distribution: Clawback",E34)),-H34, ISNUMBER(SEARCH("Distribution: Income",E34)),-H34, ISNUMBER(SEARCH("Distribution: Dividends",E34)),-H34, ISNUMBER(SEARCH("Distribution: Other (Provide explanation in far-left column)",E34)),-H34, ISNUMBER(SEARCH("Distribution: Realized Gain / (Loss) - Cash (input negative value for loss)",E34)),-H34, ISNUMBER(SEARCH("Distribution: Realized Gain / (Loss) - Stock (input negative value for loss)",E34)),-H34, ISNUMBER(SEARCH("Distribution: Return of Capital - Cash",E34)),-H34, ISNUMBER(SEARCH("Distribution: Return of Capital - Stock",E34)),-H34, ISNUMBER(SEARCH("Distribution: From NAV-Based Facility",E34)),-H34, ISNUMBER(SEARCH("Negative Contribution: Return of Excess Capital Called",E34)),-H34, ISNUMBER(SEARCH("Negative Contribution: Return of Excess Capital Called - Investments",E34)),-H34, ISNUMBER(SEARCH("Negative Contribution: Return of Excess Capital Called - Management Fees/Partnership Expenses",E34)),-H34, ISNUMBER(SEARCH("Distribution: Subsequent Close Interest",E34)),-H34, ISNUMBER(SEARCH("Distribution: Tax Withheld",E34)),H34, ISNUMBER(SEARCH("Distribution: Refund of Tax Withheld",E34)),-H34),0)} -> 0
J35: {=IFERROR(_xlfn.IFS(AND(I35="Decrease",H35<0),H35,AND(I35="Decrease",H35>0),-H35,AND(I35="Increase",H35>0),H35,AND(I35="Increase",H35<0),-H35,AND(I35="No Impact",H35=0),"0.00"),"0.00")} -> 0.00 | K35: {=IFERROR(_xlfn.IFS( ISNUMBER(SEARCH("Capital call:",E35)),H35, ISNUMBER(SEARCH("Distribution: Carry",E35)),H35, ISNUMBER(SEARCH("Distribution: Clawback",E35)),-H35, ISNUMBER(SEARCH("Distribution: Income",E35)),-H35, ISNUMBER(SEARCH("Distribution: Dividends",E35)),-H35, ISNUMBER(SEARCH("Distribution: Other (Provide explanation in far-left column)",E35)),-H35, ISNUMBER(SEARCH("Distribution: Realized Gain / (Loss) - Cash (input negative value for loss)",E35)),-H35, ISNUMBER(SEARCH("Distribution: Realized Gain / (Loss) - Stock (input negative value for loss)",E35)),-H35, ISNUMBER(SEARCH("Distribution: Return of Capital - Cash",E35)),-H35, ISNUMBER(SEARCH("Distribution: Return of Capital - Stock",E35)),-H35, ISNUMBER(SEARCH("Distribution: From NAV-Based Facility",E35)),-H35, ISNUMBER(SEARCH("Negative Contribution: Return of Excess Capital Called",E35)),-H35, ISNUMBER(SEARCH("Negative Contribution: Return of Excess Capital Called - Investments",E35)),-H35, ISNUMBER(SEARCH("Negative Contribution: Return of Excess Capital Called - Management Fees/Partnership Expenses",E35)),-H35, ISNUMBER(SEARCH("Distribution: Subsequent Close Interest",E35)),-H35, ISNUMBER(SEARCH("Distribution: Tax Withheld",E35)),H35, ISNUMBER(SEARCH("Distribution: Refund of Tax Withheld",E35)),-H35),0)} -> 0
J36: {=IFERROR(_xlfn.IFS(AND(I36="Decrease",H36<0),H36,AND(I36="Decrease",H36>0),-H36,AND(I36="Increase",H36>0),H36,AND(I36="Increase",H36<0),-H36,AND(I36="No Impact",H36=0),"0.00"),"0.00")} -> 0.00 | K36: {=IFERROR(_xlfn.IFS( ISNUMBER(SEARCH("Capital call:",E36)),H36, ISNUMBER(SEARCH("Distribution: Carry",E36)),H36, ISNUMBER(SEARCH("Distribution: Clawback",E36)),-H36, ISNUMBER(SEARCH("Distribution: Income",E36)),-H36, ISNUMBER(SEARCH("Distribution: Dividends",E36)),-H36, ISNUMBER(SEARCH("Distribution: Other (Provide explanation in far-left column)",E36)),-H36, ISNUMBER(SEARCH("Distribution: Realized Gain / (Loss) - Cash (input negative value for loss)",E36)),-H36, ISNUMBER(SEARCH("Distribution: Realized Gain / (Loss) - Stock (input negative value for loss)",E36)),-H36, ISNUMBER(SEARCH("Distribution: Return of Capital - Cash",E36)),-H36, ISNUMBER(SEARCH("Distribution: Return of Capital - Stock",E36)),-H36, ISNUMBER(SEARCH("Distribution: From NAV-Based Facility",E36)),-H36, ISNUMBER(SEARCH("Negative Contribution: Return of Excess Capital Called",E36)),-H36, ISNUMBER(SEARCH("Negative Contribution: Return of Excess Capital Called - Investments",E36)),-H36, ISNUMBER(SEARCH("Negative Contribution: Return of Excess Capital Called - Management Fees/Partnership Expenses",E36)),-H36, ISNUMBER(SEARCH("Distribution: Subsequent Close Interest",E36)),-H36, ISNUMBER(SEARCH("Distribution: Tax Withheld",E36)),H36, ISNUMBER(SEARCH("Distribution: Refund of Tax Withheld",E36)),-H36),0)} -> 0
... J53: {=IFERROR(_xlfn.IFS(AND(I53="Decrease",H53<0),H53,AND(I53="Decrease",H53>0),-H53,AND(I53="Increase",H53>0),H53,AND(I53="Increase",H53<0),-H53,AND(I53="No Impact",H53=0),"0.00"),"0.00")} -> 0.00 | K53: {=IFERROR(_xlfn.IFS( ISNUMBER(SEARCH("Capital call:",E53)),H53, ISNUMBER(SEARCH("Distribution: Carry",E53)),H53, ISNUMBER(SEARCH("Distribution: Clawback",E53)),-H53, ISNUMBER(SEARCH("Distribution: Income",E53)),-H53, ISNUMBER(SEARCH("Distribution: Dividends",E53)),-H53, ISNUMBER(SEARCH("Distribution: Other (Provide explanation in far-left column)",E53)),-H53, ISNUMBER(SEARCH("Distribution: Realized Gain / (Loss) - Cash (input negative value for loss)",E53)),-H53, ISNUMBER(SEARCH("Distribution: Realized Gain / (Loss) - Stock (input negative value for loss)",E53)),-H53, ISNUMBER(SEARCH("Distribution: Return of Capital - Cash",E53)),-H53, ISNUMBER(SEARCH("Distribution: Return of Capital - Stock",E53)),-H53, ISNUMBER(SEARCH("Distribution: From NAV-Based Facility",E53)),-H53, ISNUMBER(SEARCH("Negative Contribution: Return of Excess Capital Called",E53)),-H53, ISNUMBER(SEARCH("Negative Contribution: Return of Excess Capital Called - Investments",E53)),-H53, ISNUMBER(SEARCH("Negative Contribution: Return of Excess Capital Called - Management Fees/Partnership Expenses",E53)),-H53, ISNUMBER(SEARCH("Distribution: Subsequent Close Interest",E53)),-H53, ISNUMBER(SEARCH("Distribution: Tax Withheld",E53)),H53, ISNUMBER(SEARCH("Distribution: Refund of Tax Withheld",E53)),-H53),0)} -> 0
B56: Supplemental Calculations - Optional
B58: Management Fee Calculation (per Section X.X of LPA) | J58: Management Fee Calculation - Key Dates (Optional)
B59: Time Period | K59: Final Close Date
B60: Calculation Basis, per LPA | K60: Investment Period End Date
B61: Gross Calculation | K61: Management Fee Step-Down Date
B62: Waiver Amount | K62: Fund Term Expiration Date
B63: Fee Offset
...

Sheet Trans. Types & Definitions
A2: Transaction Type | B2: Definition | C2: Impact on Unfunded | D2: Inside or Outside
A3: Capital Call: Deemed GP Contribution from LPs | B3: Call from LPs, on behalf of GP's share of a capital call (typically serves as an offset to future management fees). | C3: Increase | D3: Inside
A4: Capital Call: Total Amount - Inside Fund | B4: Call from investors for any purpose (i.e., capital calls for investments, management fees, partnership expenses, etc., should all be included). | C4: Decrease | D4: Outside
A5: Capital Call: Total Amount - Outside Fund | B5: Call from investors for transactions occurring external to the Fund, for example, where the Fund acts as a conduit for transactions between LPs, or LPs and other external parties. | C5: No Impact
A6: Capital Call: Investments | B6: Call for investments into new or existing portfolio investments. Includes any deemed contributions that are partially or completely netted with distributions.
A7: Capital Call: Management Fees | B7: Call for periodic Management Fees as defined in the private fund’s organizational and offering documents that set forth the applicable calculation methodology, net of any waivers, offsets, rebates and discounts; Includes calls for fees both inside and outside commitment. Calls for fees inside of commitment reduce unfunded commitment, whereas calls for fees outside of commitment do not reduce unfunded commitment. Also includes any deemed contributions that are partially or completely netted with distributions.
A8: Capital Call: Partnership Expenses | B8: Call for Partnership Expenses as defined in the private fund’s organizational and offering documents, net of any offsets; Includes calls for Partnership expenses both inside and outside commitment. Calls for Partnership Expenses inside of commitment reduce unfunded commitment, whereas calls for Partnership Expenses outside of commitment do not reduce unfunded commitment. Includes any expenses related to the organization or establishment of the Fund. Also includes any deemed contributions that are partially or completely netted with distributions.
A9: Capital Call: Placement Agent Fees | B9: Call for fees/costs paid to the GP/Manager/Related Person, or to outside parties, for fundraising services or as otherwise defined in the private fund’s organizational and offering documents, net of any offsets; Includes calls for fees both inside and outside commitment. Calls for fees inside of commitment reduce unfunded commitment, whereas calls for fees outside of commitment do not reduce unfunded commitment. Includes any deemed contributions that are partially or completely netted with distributions. (May occur "outside" of the Fund's core operations in the event the Fund acts as an intermediary between an LP and a placement agent. Often LPA-specific).
A10: Capital Call: Subsequent Close Interest | B10: Call for interest due from LPs that committed to a subsequent closing of the Fund (typically occurs "outside" of the Fund's core operations as this transaction often occurs between LPs, with the Fund only serving as an intermediary).
A11: Capital Call: Working Capital | B11: Call for capital from investors when final use of funds has not been determined. Most often used by Fund of Funds or Private Credit funds that call larger amounts of capital, which often results in a balance of extra cash held by the private fund. May also be used by a Fund that maintains an extra cash balance as a contingency for unforeseen Fund expenses. Includes any deemed contributions that are partially or completely netted with distributions.
A12: Capital Call: Fund-level Subscription Facility Fees/Interest | B12: Call for fees/interest incurred by the private fund resulting from the use of a fund-level subscription facility.
A13: Capital Call: Other (Provide explanation in far-left column) | B13: Miscellaneous capital calls not otherwise defined above. A description of these calls should be provided in the Transaction Description field of the Template.
A14: Distribution: Carry | B14: GP's share of distribution proceeds, as defined by the waterfall calculation in the private fund’s organizational and offering documents (offset to distribution).
A15: Distribution: Clawback | B15: Return of excess carry distributed to GP, as defined by the waterfall calculation in the private fund’s organizational and offering documents (offset to Carry).
A16: Distribution: Income | B16: Interest income earned from portfolio investments.
A17: Distribution: Dividends | B17: Dividend income earned from portfolio investments.
... A29: Distribution: Refund of Tax Withheld | B29: Distribution to LPs resulting from an overpayment of taxes or application of a reduced rate.
A32: ='Suggested Guidance'!B22 -> ILPA Capital Call & Distribution Template (v. 2.0) – This packet was last updated on September 10, 2025
A34: ='Suggested Guidance'!B24 -> © 2025 Institutional Limited Partners Association. All rights reserved.

Sheet Summary of Revisions
D2: ='Suggested Guidance'!B22 -> ILPA Capital Call & Distribution Template (v. 2.0) – This packet was last updated on September 10, 2025
B5: Below is a summary of all changes to the Template since its original release in September 2025:
B7: No revisions as of September 10, 2025.
